[不明なエラー]
Traceback (most recent call last):
  File "C:\Users\kento\AppData\Local\Programs\Python\Python313\Lib\site-packages\pyautogui\__init__.py", line 172, in wrapper
    return wrappedFunction(*args, **kwargs)
  File "C:\Users\kento\AppData\Local\Programs\Python\Python313\Lib\site-packages\pyautogui\__init__.py", line 204, in locateCenterOnScreen
    return pyscreeze.locateCenterOnScreen(*args, **kwargs)
           ~~~~~~~~~~~~~~~~~~~~~~~~~~~~~~^^^^^^^^^^^^^^^^^
  File "C:\Users\kento\AppData\Local\Programs\Python\Python313\Lib\site-packages\pyscreeze\__init__.py", line 447, in locateCenterOnScreen
    coords = locateOnScreen(image, **kwargs)
  File "C:\Users\kento\AppData\Local\Programs\Python\Python313\Lib\site-packages\pyscreeze\__init__.py", line 405, in locateOnScreen
    retVal = locate(image, screenshotIm, **kwargs)
  File "C:\Users\kento\AppData\Local\Programs\Python\Python313\Lib\site-packages\pyscreeze\__init__.py", line 383, in locate
    points = tuple(locateAll(needleImage, haystackImage, **kwargs))
  File "C:\Users\kento\AppData\Local\Programs\Python\Python313\Lib\site-packages\pyscreeze\__init__.py", line 257, in _locateAll_opencv
    raise ImageNotFoundException('Could not locate the image (highest confidence = %.3f)' % result.max())
pyscreeze.ImageNotFoundException: Could not locate the image (highest confidence = 0.684)

During handling of the above exception, another exception occurred:

Traceback (most recent call last):
  File "C:\Users\kento\Desktop\AutoClickerApp\main.py", line 12, in start_script
    run_script(file_path)
    ~~~~~~~~~~^^^^^^^^^^^
  File "C:\Users\kento\Desktop\AutoClickerApp\actions.py", line 21, in run_script
    location = pyautogui.locateCenterOnScreen(target, confidence=0.8)
  File "C:\Users\kento\AppData\Local\Programs\Python\Python313\Lib\site-packages\pyautogui\__init__.py", line 174, in wrapper
    raise ImageNotFoundException  # Raise PyAutoGUI's ImageNotFoundException.
    ^^^^^^^^^^^^^^^^^^^^^^^^^^^^
pyautogui.ImageNotFoundException


[不明なエラー]
Traceback (most recent call last):
  File "C:\Users\kento\AppData\Local\Programs\Python\Python313\Lib\site-packages\pyautogui\__init__.py", line 172, in wrapper
    return wrappedFunction(*args, **kwargs)
  File "C:\Users\kento\AppData\Local\Programs\Python\Python313\Lib\site-packages\pyautogui\__init__.py", line 204, in locateCenterOnScreen
    return pyscreeze.locateCenterOnScreen(*args, **kwargs)
           ~~~~~~~~~~~~~~~~~~~~~~~~~~~~~~^^^^^^^^^^^^^^^^^
  File "C:\Users\kento\AppData\Local\Programs\Python\Python313\Lib\site-packages\pyscreeze\__init__.py", line 447, in locateCenterOnScreen
    coords = locateOnScreen(image, **kwargs)
  File "C:\Users\kento\AppData\Local\Programs\Python\Python313\Lib\site-packages\pyscreeze\__init__.py", line 405, in locateOnScreen
    retVal = locate(image, screenshotIm, **kwargs)
  File "C:\Users\kento\AppData\Local\Programs\Python\Python313\Lib\site-packages\pyscreeze\__init__.py", line 383, in locate
    points = tuple(locateAll(needleImage, haystackImage, **kwargs))
  File "C:\Users\kento\AppData\Local\Programs\Python\Python313\Lib\site-packages\pyscreeze\__init__.py", line 257, in _locateAll_opencv
    raise ImageNotFoundException('Could not locate the image (highest confidence = %.3f)' % result.max())
pyscreeze.ImageNotFoundException: Could not locate the image (highest confidence = 0.746)

During handling of the above exception, another exception occurred:

Traceback (most recent call last):
  File "C:\Users\kento\Desktop\AutoClickerApp\main.py", line 12, in start_script
    run_script(file_path)
    ~~~~~~~~~~^^^^^^^^^^^
  File "C:\Users\kento\Desktop\AutoClickerApp\actions.py", line 21, in run_script
    location = pyautogui.locateCenterOnScreen(target, confidence=0.8)
  File "C:\Users\kento\AppData\Local\Programs\Python\Python313\Lib\site-packages\pyautogui\__init__.py", line 174, in wrapper
    raise ImageNotFoundException  # Raise PyAutoGUI's ImageNotFoundException.
    ^^^^^^^^^^^^^^^^^^^^^^^^^^^^
pyautogui.ImageNotFoundException


[画像エラー]
画面上に画像が見つかりません: assets/kurarowa_icon.png

[不明なエラー]
Traceback (most recent call last):
  File "C:\Users\kento\Desktop\AutoClickerApp\main.py", line 12, in start_script
    run_script(file_path)
    ~~~~~~~~~~^^^^^^^^^^^
  File "C:\Users\kento\Desktop\AutoClickerApp\actions.py", line 52, in run_script
    _execute_action(step)
    ~~~~~~~~~~~~~~~^^^^^^
  File "C:\Users\kento\Desktop\AutoClickerApp\actions.py", line 21, in _execute_action
    location = pyautogui.locateCenterOnScreen(target, confidence=0.7)
  File "C:\Users\kento\AppData\Local\Programs\Python\Python313\Lib\site-packages\pyautogui\__init__.py", line 172, in wrapper
    return wrappedFunction(*args, **kwargs)
  File "C:\Users\kento\AppData\Local\Programs\Python\Python313\Lib\site-packages\pyautogui\__init__.py", line 204, in locateCenterOnScreen
    return pyscreeze.locateCenterOnScreen(*args, **kwargs)
           ~~~~~~~~~~~~~~~~~~~~~~~~~~~~~~^^^^^^^^^^^^^^^^^
  File "C:\Users\kento\AppData\Local\Programs\Python\Python313\Lib\site-packages\pyscreeze\__init__.py", line 447, in locateCenterOnScreen
    coords = locateOnScreen(image, **kwargs)
  File "C:\Users\kento\AppData\Local\Programs\Python\Python313\Lib\site-packages\pyscreeze\__init__.py", line 405, in locateOnScreen
    retVal = locate(image, screenshotIm, **kwargs)
  File "C:\Users\kento\AppData\Local\Programs\Python\Python313\Lib\site-packages\pyscreeze\__init__.py", line 383, in locate
    points = tuple(locateAll(needleImage, haystackImage, **kwargs))
  File "C:\Users\kento\AppData\Local\Programs\Python\Python313\Lib\site-packages\pyscreeze\__init__.py", line 231, in _locateAll_opencv
    needleImage = _load_cv2(needleImage, grayscale)
  File "C:\Users\kento\AppData\Local\Programs\Python\Python313\Lib\site-packages\pyscreeze\__init__.py", line 193, in _load_cv2
    raise IOError(
    ...<3 lines>...
    )
OSError: Failed to read assets/トロ上げ/バトル開始.png because file is missing, has improper permissions, or is an unsupported or invalid format


[画像エラー]
画面上に画像が見つかりません: assets/kurarowa_icon.png

[画像エラー]
画面上に画像が見つかりません: assets/kurarowa/start.png

[画像エラー]
画像ファイルが存在しません: assets/クラロワ/end.png

[画像エラー]
画面上に画像が見つかりません: assets/kurarowa/start.png

[画像エラー]
画面上に画像が見つかりません: assets/batoru.png

[画像エラー]
画像ファイルが存在しません: assets/クラロワ/end.png

[不明なエラー]
Traceback (most recent call last):
  File "C:\Users\kento\Desktop\AutoClickerApp\main.py", line 12, in start_script
    run_script(file_path)
    ~~~~~~~~~~^^^^^^^^^^^
  File "C:\Users\kento\Desktop\AutoClickerApp\actions.py", line 62, in run_script
    if _execute_action(loop_step):
       ~~~~~~~~~~~~~~~^^^^^^^^^^^
  File "C:\Users\kento\Desktop\AutoClickerApp\actions.py", line 32, in _execute_action
    location = pyautogui.locateCenterOnScreen(target, confidence=0.7)
  File "C:\Users\kento\AppData\Local\Programs\Python\Python313\Lib\site-packages\pyautogui\__init__.py", line 172, in wrapper
    return wrappedFunction(*args, **kwargs)
  File "C:\Users\kento\AppData\Local\Programs\Python\Python313\Lib\site-packages\pyautogui\__init__.py", line 204, in locateCenterOnScreen
    return pyscreeze.locateCenterOnScreen(*args, **kwargs)
           ~~~~~~~~~~~~~~~~~~~~~~~~~~~~~~^^^^^^^^^^^^^^^^^
  File "C:\Users\kento\AppData\Local\Programs\Python\Python313\Lib\site-packages\pyscreeze\__init__.py", line 447, in locateCenterOnScreen
    coords = locateOnScreen(image, **kwargs)
  File "C:\Users\kento\AppData\Local\Programs\Python\Python313\Lib\site-packages\pyscreeze\__init__.py", line 405, in locateOnScreen
    retVal = locate(image, screenshotIm, **kwargs)
  File "C:\Users\kento\AppData\Local\Programs\Python\Python313\Lib\site-packages\pyscreeze\__init__.py", line 383, in locate
    points = tuple(locateAll(needleImage, haystackImage, **kwargs))
  File "C:\Users\kento\AppData\Local\Programs\Python\Python313\Lib\site-packages\pyscreeze\__init__.py", line 231, in _locateAll_opencv
    needleImage = _load_cv2(needleImage, grayscale)
  File "C:\Users\kento\AppData\Local\Programs\Python\Python313\Lib\site-packages\pyscreeze\__init__.py", line 211, in _load_cv2
    raise TypeError('expected an image filename, OpenCV numpy array, or PIL image')
TypeError: expected an image filename, OpenCV numpy array, or PIL image


[画像エラー]
画面上に画像が見つかりません: assets/クラロワ/end.png

[画像エラー]
画面上に画像が見つかりません: assets/クラロワ/end.png

[画像エラー]
画面上に画像が見つかりません: assets/クラロワ/end.png

[画像エラー]
画面上に画像が見つかりません: assets/クラロワ/end.png

[画像エラー]
画面上に画像が見つかりません: assets/kurarowa/end.png

[画像エラー]
画面上に画像が見つかりません: assets/kurarowa/end.png

[画像エラー]
画面上に画像が見つかりません: assets/kurarowa/end.png

[画像エラー]
画面上に画像が見つかりません: assets/kurarowa/end.png

[画像エラー]
画面上に画像が見つかりません: assets/kurarowa/end.png

[画像エラー]
画面上に画像が見つかりません: assets/kurarowa/end.png

[画像エラー]
画面上に画像が見つかりません: assets/kurarowa/end.png

[画像エラー]
画面上に画像が見つかりません: assets/kurarowa/end.png

[画像エラー]
画面上に画像が見つかりません: assets/kurarowa/end.png

[画像エラー]
画面上に画像が見つかりません: assets/kurarowa/end.png

[画像エラー]
画面上に画像が見つかりません: assets/kurarowa/end.png

[画像エラー]
画面上に画像が見つかりません: assets/kurarowa/end.png

[画像エラー]
画面上に画像が見つかりません: assets/kurarowa/start.png

[画像エラー]
画面上に画像が見つかりません: assets/kurarowa/start.png

[画像エラー]
画面上に画像が見つかりません: assets/kurarowa/start.png

[画像エラー]
画面上に画像が見つかりません: assets/batoru.png

[画像エラー]
画面上に画像が見つかりません: assets/batoru.png

[不明なエラー]
Traceback (most recent call last):
  File "C:\Users\kento\Desktop\AutoClickerApp\main.py", line 24, in start_script
    run_script(file_path, stop_event)
    ~~~~~~~~~~^^^^^^^^^^^^^^^^^^^^^^^
  File "C:\Users\kento\Desktop\AutoClickerApp\actions.py", line 100, in run_script
    return 'global_break'
    ^^^^^^^^^^^^
  File "C:\Users\kento\Desktop\AutoClickerApp\actions.py", line 83, in process_steps
    return 'global_break'
                       ^^
  File "C:\Users\kento\Desktop\AutoClickerApp\actions.py", line 80, in process_steps
    """
    
TypeError: 'str' object cannot be interpreted as an integer


[不明なエラー]
Traceback (most recent call last):
  File "C:\Users\kento\Desktop\AutoClickerApp\main.py", line 24, in start_script
    run_script(file_path, stop_event)
    ~~~~~~~~~~^^^^^^^^^^^^^^^^^^^^^^^
  File "C:\Users\kento\Desktop\AutoClickerApp\actions.py", line 100, in run_script
    except (ValueError, TypeError):
    ^^^^^^^^^^^^^^^^^^^^
  File "C:\Users\kento\Desktop\AutoClickerApp\actions.py", line 83, in process_steps
    return 'global_break'
                       ^^
  File "C:\Users\kento\Desktop\AutoClickerApp\actions.py", line 80, in process_steps
    """
    
TypeError: 'str' object cannot be interpreted as an integer


[不明なエラー]
Traceback (most recent call last):
  File "C:\Users\kento\Desktop\AutoClickerApp\main.py", line 24, in start_script
    run_script(file_path, stop_event)
    ~~~~~~~~~~^^^^^^^^^^^^^^^^^^^^^^^
  File "C:\Users\kento\Desktop\AutoClickerApp\actions.py", line 100, in run_script
    loop_count = int(count)
    ^^^^^^^^^^^^^^^^
  File "C:\Users\kento\Desktop\AutoClickerApp\actions.py", line 83, in process_steps
    return 'global_break'
                       ^^
  File "C:\Users\kento\Desktop\AutoClickerApp\actions.py", line 80, in process_steps
    """
    
TypeError: 'str' object cannot be interpreted as an integer


[不明なエラー]
Traceback (most recent call last):
  File "C:\Users\kento\Desktop\AutoClickerApp\main.py", line 24, in start_script
    run_script(file_path, stop_event)
    ~~~~~~~~~~^^^^^^^^^^^^^^^^^^^^^^^
  File "C:\Users\kento\Desktop\AutoClickerApp\actions.py", line 100, in run_script
    try:
  File "C:\Users\kento\Desktop\AutoClickerApp\actions.py", line 83, in process_steps
    """
    
  File "C:\Users\kento\Desktop\AutoClickerApp\actions.py", line 80, in process_steps
    """
    
TypeError: 'str' object cannot be interpreted as an integer


[不明なエラー]
Traceback (most recent call last):
  File "C:\Users\kento\Desktop\AutoClickerApp\main.py", line 24, in start_script
    run_script(file_path, stop_event)
    ~~~~~~~~~~^^^^^^^^^^^^^^^^^^^^^^^
  File "C:\Users\kento\Desktop\AutoClickerApp\actions.py", line 100, in run_script
    if break_signal == 'global_break':
    ^^^^^^^^^^^^^^^^
  File "C:\Users\kento\Desktop\AutoClickerApp\actions.py", line 83, in process_steps
  File "C:\Users\kento\Desktop\AutoClickerApp\actions.py", line 80, in process_steps
    # 現在のループのみ中断
TypeError: 'str' object cannot be interpreted as an integer


[不明なエラー]
Traceback (most recent call last):
  File "C:\Users\kento\Desktop\AutoClickerApp\main.py", line 24, in start_script
    run_script(file_path, stop_event)
    ~~~~~~~~~~^^^^^^^^^^^^^^^^^^^^^^^
  File "C:\Users\kento\Desktop\AutoClickerApp\actions.py", line 100, in run_script
    if break_signal == 'global_break':
    ^^^^^^^^^^^^^^^^
  File "C:\Users\kento\Desktop\AutoClickerApp\actions.py", line 83, in process_steps
  File "C:\Users\kento\Desktop\AutoClickerApp\actions.py", line 80, in process_steps
    # 現在のループのみ中断
TypeError: 'str' object cannot be interpreted as an integer


[画像エラー]
画面上に画像が見つかりません: assets/kurarowa/end.png

[画像エラー]
画面上に画像が見つかりません: assets/kurarowa/start.png

[画像エラー]
画面上に画像が見つかりません: assets/kurarowa/start.png

[不明なエラー]
Traceback (most recent call last):
  File "C:\Users\kento\Desktop\AutoClickerApp\main.py", line 24, in start_script
    run_script(file_path, stop_event)
    ~~~~~~~~~~^^^^^^^^^^^^^^^^^^^^^^^
  File "C:\Users\kento\Desktop\AutoClickerApp\actions.py", line 157, in run_script
    process_steps(steps, stop_event)
    ~~~~~~~~~~~~~^^^^^^^^^^^^^^^^^^^
  File "C:\Users\kento\Desktop\AutoClickerApp\actions.py", line 120, in process_steps
    break_signal = process_steps(loop_steps, stop_event)
  File "C:\Users\kento\Desktop\AutoClickerApp\actions.py", line 106, in process_steps
    break_signal = process_steps(loop_steps, stop_event)
  File "C:\Users\kento\Desktop\AutoClickerApp\actions.py", line 127, in process_steps
    image_path = config['image']
                 ~~~~~~^^^^^^^^^
TypeError: 'NoneType' object is not subscriptable


[不明なエラー]
Traceback (most recent call last):
  File "C:\Users\kento\Desktop\AutoClickerApp\main.py", line 24, in start_script
    run_script(file_path, stop_event)
    ~~~~~~~~~~^^^^^^^^^^^^^^^^^^^^^^^
  File "C:\Users\kento\Desktop\AutoClickerApp\actions.py", line 157, in run_script
    process_steps(steps, stop_event)
    ~~~~~~~~~~~~~^^^^^^^^^^^^^^^^^^^
  File "C:\Users\kento\Desktop\AutoClickerApp\actions.py", line 120, in process_steps
    break_signal = process_steps(loop_steps, stop_event)
  File "C:\Users\kento\Desktop\AutoClickerApp\actions.py", line 106, in process_steps
    break_signal = process_steps(loop_steps, stop_event)
  File "C:\Users\kento\Desktop\AutoClickerApp\actions.py", line 127, in process_steps
    image_path = config['image']
                 ~~~~~~^^^^^^^^^
TypeError: 'NoneType' object is not subscriptable


[不明なエラー]
Traceback (most recent call last):
  File "C:\Users\kento\Desktop\AutoClickerApp\main.py", line 24, in start_script
    run_script(file_path, stop_event)
    ~~~~~~~~~~^^^^^^^^^^^^^^^^^^^^^^^
  File "C:\Users\kento\Desktop\AutoClickerApp\actions.py", line 157, in run_script
    process_steps(steps, stop_event)
    ~~~~~~~~~~~~~^^^^^^^^^^^^^^^^^^^
  File "C:\Users\kento\Desktop\AutoClickerApp\actions.py", line 120, in process_steps
    break_signal = process_steps(loop_steps, stop_event)
  File "C:\Users\kento\Desktop\AutoClickerApp\actions.py", line 106, in process_steps
    break_signal = process_steps(loop_steps, stop_event)
  File "C:\Users\kento\Desktop\AutoClickerApp\actions.py", line 127, in process_steps
    image_path = config['image']
                 ~~~~~~^^^^^^^^^
TypeError: 'NoneType' object is not subscriptable


[画像エラー]
画面上に画像が見つかりません: assets/kurarowa/start.png

[画像エラー]
画面上に画像が見つかりません: assets/kurarowa/end.png

[画像エラー]
画面上に画像が見つかりません: assets/kurarowa/start.png

[画像エラー]
画面上に画像が見つかりません: assets/kurarowa/start.png

[画像エラー]
画面上に画像が見つかりません: assets/kurarowa/start.png

[画像エラー]
画面上に画像が見つかりません: assets/batoruStr.png

[画像エラー]
画面上に画像が見つかりません: assets/batoruStr.png

[画像エラー]
画面上に画像が見つかりません: assets/saisenn.png

[画像エラー]
画面上に画像が見つかりません: assets/saisenn.png

[画像エラー]
画面上に画像が見つかりません: assets/saisenn.png

[不明なエラー]
Traceback (most recent call last):
  File "C:\Users\kento\Desktop\AutoClickerApp\main.py", line 24, in start_script
    run_script(file_path, stop_event)
    ~~~~~~~~~~^^^^^^^^^^^^^^^^^^^^^^^
  File "C:\Users\kento\Desktop\AutoClickerApp\actions.py", line 181, in run_script
    process_steps(steps, stop_event)
    ~~~~~~~~~~~~~^^^^^^^^^^^^^^^^^^^
  File "C:\Users\kento\Desktop\AutoClickerApp\actions.py", line 144, in process_steps
    break_signal = process_steps(loop_steps, stop_event)
  File "C:\Users\kento\Desktop\AutoClickerApp\actions.py", line 144, in process_steps
    break_signal = process_steps(loop_steps, stop_event)
  File "C:\Users\kento\Desktop\AutoClickerApp\actions.py", line 170, in process_steps
    break_signal = _execute_action(step, stop_event)
  File "C:\Users\kento\Desktop\AutoClickerApp\actions.py", line 89, in _execute_action
    pyautogui.moveTo(x, y, duration=0.7)
    ~~~~~~~~~~~~~~~~^^^^^^^^^^^^^^^^^^^^
  File "C:\Users\kento\AppData\Local\Programs\Python\Python313\Lib\site-packages\pyautogui\__init__.py", line 593, in wrapper
    failSafeCheck()
    ~~~~~~~~~~~~~^^
  File "C:\Users\kento\AppData\Local\Programs\Python\Python313\Lib\site-packages\pyautogui\__init__.py", line 1734, in failSafeCheck
    raise FailSafeException(
        "PyAutoGUI fail-safe triggered from mouse moving to a corner of the screen. To disable this fail-safe, set pyautogui.FAILSAFE to False. DISABLING FAIL-SAFE IS NOT RECOMMENDED."
    )
pyautogui.FailSafeException: PyAutoGUI fail-safe triggered from mouse moving to a corner of the screen. To disable this fail-safe, set pyautogui.FAILSAFE to False. DISABLING FAIL-SAFE IS NOT RECOMMENDED.


[画像エラー]
画面上に画像が見つかりません: assets/saisenn.png

[画像エラー]
画面上に画像が見つかりません: assets/saisenn.png

[画像エラー]
画面上に画像が見つかりません: assets/saisenn.png

[画像エラー]
画面上に画像が見つかりません: assets/saisenn.png

[画像エラー]
画面上に画像が見つかりません: assets/saisenn.png

[画像エラー]
画面上に画像が見つかりません: assets/saisenn.png

[画像エラー]
画面上に画像が見つかりません: assets/saisenn.png

